# Exception Handling

**Exceptions** are runtime errors that interrupt the normal flow of a program. Unhandled exceptions will cause the program to terminate.  **Exception handling** allows a program to continue running or exit gracefully when an exception occurs. 

## Python Documentation References {.hide}

**Python Documentation References:**

- [Built-in exceptions](https://docs.python.org/3/library/exceptions.html)
- [Exception hierarchy](https://docs.python.org/3.12/library/exceptions.html#exception-hierarchy)
- [Raising exceptions](https://docs.python.org/3/tutorial/errors.html#raising-exceptions)

## Exception Types


### Common Exceptions {.hide}


::: {.r-stack}

```{.python code-line-numbers="1-5"}
try:
    # some code
except <ExceptionType>:
    # handle specific exception


```

::: {.fragment .fade-in-then-out .absolute width="100%"}
```{.python code-line-numbers="1-4"}
try:
    1 / 0
except ZeroDivisionError:
    print("ZeroDivisionError")


```
A `ZeroDivisionError` is raised when dividing by zero.
:::

::: {.fragment .fade-in-then-out .absolute width="100%"}
```{.python code-line-numbers="1-4"}
try:
    int("abc")
except TypeError:
    print("TypeError")


```
A `TypeError` is raised when performing invalid operations between incompatible types.
:::

::: {.fragment .fade-in-then-out .absolute width="100%"}
```{.python code-line-numbers="1-5"}
list = [1, 2, 3]
try:
    list[3]
except IndexError:
    print("IndexError")
```
An `IndexError` is raised when accessing an index that is out of range.
:::

::: {.fragment .fade-in-then-out .absolute width="100%"}
```{.python code-line-numbers="1-5"}
dict = {"name": "Jane"}
try:
    dict["email"]
except KeyError:
    print("KeyError")
```
A `KeyError` is raised when accessing a non-existent dictionary key.
:::

:::

### `ValueError` Exercise {.exercise}

A `ValueError` is raised when a function receives an inappropriate value.

::: {.r-stack}

::: {.absolute width="100%"}
```{.python filename="test.py"}
import math
math.sqrt(-1)
```
:::

::: {.fragment .fade-in-then-out .absolute width="100%"}

```{.python filename="test.py"}
import math
math.sqrt(-1)
```
<br>

```{.bash code-line-numbers="false"}
$ python test.py

Traceback (most recent call last):
  File "/workspaces/20CS2023/test.py", line 2, in <module>
    math.sqrt(-1)
ValueError: math domain error
```
:::

:::

## Exception Handling Mechanism {.hide}

Python's exception handling mechanism is the `try`/`except` model.

::: {.smaller-80}

::: {.r-stack}
```{.python}
try:
    # some code
except:
    # handle exception
else:
    # execute if no exception
finally:
    # cleanup code
```
::: {.fragment .fade-in-then-out .absolute .top-0 .left-0 width="100%"}
```{.python code-line-numbers="1-2"}
try:
    # some code
except:
    # handle exception
else:
    # execute if no exception
finally:
    # cleanup code
```
**`try`: Block**

- Contains the code that might raise an exception.
- If an exception is raised within this block, control will immediately pass to the `except` block.
:::

::: {.fragment .fade-in-then-out .absolute .top-0 .left-0 width="100%"}
```{.python code-line-numbers="3-4"}
try:
    # some code
except:
    # handle exception
else:
    # execute if no exception
finally:
    # cleanup code
```
**`except:` Block**

- Contains the code to handle the exception if one occurs.

:::

::: {.fragment .fade-in-then-out .absolute .top-0 .left-0 width="100%"}
```{.python code-line-numbers="5-6"}
try:
    # some code
except:
    # handle exception
else:
    # execute if no exception
finally:
    # cleanup code
```
**`else:` Block** (_optional_)

- This block runs only if no exceptions are raised in the `try` block.
- It allows you to execute code that should only happen when the `try` block was successful, allowing the `try` block to only contain the code that could raise an exception.
:::

::: {.fragment .fade-in-then-out .absolute .top-0 .left-0 width="100%"}
```{.python code-line-numbers="7-8"}
try:
    # some code
except:
    # handle exception
else:
    # execute if no exception
finally:
    # cleanup code
```
**`finally:` Block** (_optional_)

- This block will always execute after the `try` and `except` blocks, regardless of whether an exception was raised or not.
- Itâ€™s typically used for cleanup operations like closing files, releasing resources, or undoing partial changes.

:::

:::


:::

## Catching and Handling Exceptions

::: {.smaller-90}
- **Catching an exception** means detecting an error when it occurs.
- **Handling an exception** means deciding what to do after catching the error, like logging it, cleaning up, or providing a fallback.
:::


### Catching All Exceptions {.hide}

```{.python code-line-numbers="3-5"}
try:
    # some code
except:
    # handle exceptions
    # even those you didn't expect -- this is bad practice
```
The generic `except` block will catch **all** errors -- this is not recommended.  **You should always catch specific exceptions**.


### Handling a `ValueError` Exception {.exercise}

Catch the `ValueError` exception:

::: {.r-stack}

::: {.absolute width="100%"}
```{.python filename="test.py"}
try:
    import math
    math.sqrt(-1)
except ValueError:
    print("ValueError")
```
:::

::: {.fragment .fade-in-then-out .absolute width="100%"}

```{.python filename="test.py"}
try:
    import math
    math.sqrt(-1)
except ValueError:
    print("ValueError")
```
<br>

```{.bash code-line-numbers="false"}
$ python test.py

ValueError
```
:::

:::

### Catching Multiple Exceptions {.hide}

You can handle multiple exceptions by adding multiple `except`.

```{.python code-line-numbers="6,9"}
def process_data(data):
    try:
        value = int(data)
        result = 100 / value
        return result
    except ValueError:
        print("Invalid data: cannot convert to integer")
        return None
    except ZeroDivisionError:
        print("Invalid data: cannot divide by zero")
        return None
```


### Catching Groups of Exceptions {.hide}

You can group exceptions into a single `except` block using parentheses.  This is useful when you want to handle multiple exceptions in the same way.

```{.python code-line-numbers="5"}
def divide_numbers(a, b):
    try:
        result = a / b
        return result
    except (ValueError, TypeError, ZeroDivisionError):
        print(f"An error occurred.")
        return None
```

::: {.notes}
Grouping exceptions can be useful when you need to handle multiple different exceptions in the same way. It helps keep the code cleaner and reduces redundancy. An example where grouping exceptions makes sense is a mathemetical operation that involves type mismatches and mathematical operations that are invalid.
:::


## The `as` Keyword {.hide}

:::{.smaller-70}

The `as` keyword in exception handling allows you to capture the raised exception object, giving you access to its details.

```python
try:
    # Some code that might raise an exception
    result = 10 / 0
except ZeroDivisionError as e:
    print(f"Error occurred: {e}")
    print(f"Error type: {type(e).__name__}")
```

**Key points:**

- `as e` assigns the exception object to the variable `e` (can be any valid variable name, but `e` is commonly used)
- Provide access to exception attributes like:
  - `e.__class__`: The exception's class
  - `str(e)`: The exception's message
- Useful for:
  - Logging detailed error information
  - Conditional handling based on exception details
  - Re-raising exceptions with additional context
:::

::: {.notes}
The `as` keyword in exception handling allows you to capture the raised exception object, giving you access to its details  -- this is dependent on the exception object's attributes.
:::

### `as` Keyword Exercise {.exercise}

::: {.r-stack}

::: {.absolute width="100%"}
```{.python filename="test.py"}
try:
    import math
    math.sqrt(-1)
except ValueError as e:
    print(f"Error occurred: {e}")
    print(f"Error type: {type(e).__name__}")
```
:::

::: {.fragment .fade-in-then-out .absolute width="100%"}

```{.python filename="test.py"}
try:
    import math
    math.sqrt(-1)
except ValueError as e:
    print(f"Error occurred: {e}")
    print(f"Error type: {type(e).__name__}")
```
<br>

```{.bash code-line-numbers="false"}
$ python test.py

Error occurred: math domain error
Error type: ValueError
```
:::

:::


## Raising Exceptions {.hide}

:::{.smaller-90}
You can manually raise exceptions using the `raise` keyword. This is useful for enforcing application-specific constraints or when detecting an error condition that Python's built-in checks don't cover.

```{.python}
def validate_age(age):
    if not isinstance(age, (int, float)):
        raise TypeError("Age must be a number")
    if age < 0:
        raise ValueError("Age cannot be negative")
    return age

try:
    validate_age(-5)
except (ValueError, TypeError):
    print(f"Validation error")
```
:::

## Precedence Rules for Return Statements {.hide}

::: {.smaller-85}
Precendence rules for return statements in exception handling blocks:
:::

::: {.smaller-60}

| Block    | Execution Condition | Return Behavior | Notes |
|----------|---------------------|-----------------|-------|
| `try`     | Always attempts to execute | If it contains a `return` statement, this value is returned (unless overridden by `finally`) | |
| `except`  | Executes if an exception occurs in `try` | If it contains a `return` statement, this value is returned (unless overridden by `finally`) | |
| `else`    | Executes if `try` completes without an exception and without executing a `return` | If it contains a `return` statement, this value is returned (unless overridden by `finally`) | Does not execute if `try` has already executed a `return` statement |
| `finally` | Always executes if present | **Overrides** all other `return` statements | Executes regardless of whether a `return` statement was encountered in other blocks. |

: {tbl-colwidths="[15,25,30,30]"}

:::

### Precedence Rules Exercise {.exercise}

::: {.smaller-80}
**Observe the output to verify the precedence rules.:**

::: {.smaller-85}
1. Run the code below as is.
2. Replace `return "From finally block"` with `pass` and run again
3. Remove `return "From try block"` and run again
:::

```{.python}
def test_function(value):
    try:
        if value == 0:
            raise ValueError("An error occurred!")
        return "From try block"
    except ValueError:
        return "From except block"
    else:
        return "From else block"
    finally:
        return "From finally block"

# Test different inputs:
print(test_function(1))  # Test with value = 1
print(test_function(0))  # Test with value = 0
```

:::


## Custom Exceptions

### Sublcassing `Exception` Class {.hide}

:::{.smaller-80}
**User-defined exceptions** can be created by subclassing the built-in `Exception` class or its subclasses. These are beneficial when you need more specific error signaling that standard exceptions don't adequately cover.


```python
class InsufficientFundsError(Exception):
    def __init__(self, balance, amount):
        self.balance = balance
        self.amount = amount
        super().__init__(f"Insufficient funds: balance {balance}, required {amount}")
```

- This class extends `Exception` to create a new type of error.
- The `super().__init__()` call ensures proper initialization of the base `Exception` class.
- Custom attributes (`balance` and `amount`) provide more context for the error.

:::

::: {.notes}

best practices when creating custom exceptions:
- Derive custom exceptions from Python's built-in exceptions when appropriate (e.g., `ValueError`, `TypeError`).
- Use descriptive names for custom exceptions (e.g., `InsufficientFundsError` instead of `MyError`).
- Include relevant error information in the exception message and as attributes.
- Document your custom exceptions, especially if they're part of a library or API.
:::


### Custom-Exception Example {.exercise}

:::{.smaller-75}

```python
class InsufficientFundsError(Exception):
    def __init__(self, balance, amount):
        self.balance = balance
        self.amount = amount
        super().__init__(f"Insufficient funds: balance {balance}, required {amount}")

def withdraw(balance, amount):
    if balance < amount:
        raise InsufficientFundsError(balance, amount)
    return balance - amount

try:
    withdraw(100, 150)
except InsufficientFundsError as e:
    print(f"Transaction failed: {e}")
    print(f"Current balance: {e.balance}")
    print(f"Attempted withdrawal: {e.amount}")
```

<br>

::: {.r-stack}

::: {.fragment .fade-in-then-out .absolute width="100%"}

```{.bash code-line-numbers="false"}
$ python test.py

```

:::

::: {.fragment .fade-in .absolute width="100%"}

```{.bash code-line-numbers="false"}
$ python test.py

Transaction failed: Insufficient funds: balance 100, required 150
Current balance: 100
Attempted withdrawal: 150
```

:::

:::


:::

:::{.notes}
**Key Points:**

- The `withdraw` function raises `InsufficientFundsError` if the amount exceeds the balance.
- In the `except` block, we can access the custom attributes of our exception.

:::

### When to Use Custom Exceptions {.hide}

:::{.smaller-85}


**Use custom exceptions to:**

- Define error types that are **specific and meaningful** to your application's domain, improving code clarity and intent.
- Facilitate **more effective debugging and targeted error handling** by distinguishing between different types of errors.
- Enhance **clarity and informativeness** of error messages by including **custom attributes** that provide detailed context about the error.

:::

::: {.callout-note}
Use custom exceptions only when they significantly improve error handling, enhance code clarity, or provide crucial domain-specific information.
:::

